Workbook

Sheet Sheet6
A3: Average of claim | B3: Smoker
A4: BMI Group | B4: No | C4: Yes | D4: Average claims
A5: <20 | B5: 6083.7122 | C5: 17978.206 | D5: 8802.4537
A6: 20-25 | B6: 7624.702 | C6: 20156.056 | D6: 10456.306
A7: 25-30 | B7: 8299.4799 | C7: 22495.874 | D7: 11000.079
A8: 30-35 | B8: 8545.0078 | C8: 39551.785 | D8: 14298.843
A9: 35+ | B9: 9192.3874 | C9: 43536.714 | D9: 17027.187
A10: Average claims | B10: 8421.1216 | C10: 32050.232 | D10: 13252.746

Sheet insurance final cleaned
A1: PatientID | B1: age | C1: gender | D1: bmi | E1: bloodpressure | F1: diabetic | G1: children | H1: smoker | I1: region | J1: claim | K1: BMI Group | L1: BMI_Smoker | M1: Is Southeast | N1: Is Southwest | O1: Is Northwest | P1: Randomizer | Q1: Is Smoker | R1: Is Diabetic | S1: Is Female | T1: Predicted Claim | U1: Residual
A2: 1 | B2: 39 | C2: male | D2: 23.2 | E2: 91 | F2: Yes | G2: 0 | H2: No | I2: southeast | J2: 1121.87 | K2: =IF(D2<20, "<20", IF(D2<25, "20-25", IF(D2<30, "25-30", IF(D2<35, "30-35", "35+")))) -> 20-25 | L2: =D2*Q2 -> 0 | M2: =IF(I2="southeast", 1, 0) -> 1 | N2: =IF(I2="southwest", 1, 0) -> 0 | O2: =IF(I2="northwest", 1, 0) -> 0 | P2: 0.71471674 | Q2: =IF(H2="Yes", 1, 0) -> 0 | R2: =IF(F2="yes", 1, 0) -> 1 | S2: =IF(C2="female", 1, 0) -> 0 | T2: =-7277.71 + (-1.28*B2) + (85.5*D2) + (738.24*G2) + (159.59*E2) + (1259.19*L2) + (-3644.73*M2) + (-2956.11*N2) + (-2948.04*O2) + (-17828.85*Q2) + (-69.06*R2) + (444.95*S2) -> 5464.87 | U2: =J2-T2 -> -4343
A3: 2 | B3: 24 | C3: male | D3: 30.1 | E3: 87 | F3: No | G3: 0 | H3: No | I3: southeast | J3: 1131.51 | K3: =IF(D3<20, "<20", IF(D3<25, "20-25", IF(D3<30, "25-30", IF(D3<35, "30-35", "35+")))) -> 30-35 | L3: =D3*Q3 -> 0 | M3: =IF(I3="southeast", 1, 0) -> 1 | N3: =IF(I3="southwest", 1, 0) -> 0 | O3: =IF(I3="northwest", 1, 0) -> 0 | P3: 0.95799828 | Q3: =IF(H3="Yes", 1, 0) -> 0 | R3: =IF(F3="yes", 1, 0) -> 0 | S3: =IF(C3="female", 1, 0) -> 0 | T3: =-7277.71 + (-1.28*B3) + (85.5*D3) + (738.24*G3) + (159.59*E3) + (1259.19*L3) + (-3644.73*M3) + (-2956.11*N3) + (-2948.04*O3) + (-17828.85*Q3) + (-69.06*R3) + (444.95*S3) -> 5504.72 | U3: =J3-T3 -> -4373.21
A4: 3 | B4: 38 | C4: male | D4: 33.3 | E4: 82 | F4: Yes | G4: 0 | H4: No | I4: southeast | J4: 1135.94 | K4: =IF(D4<20, "<20", IF(D4<25, "20-25", IF(D4<30, "25-30", IF(D4<35, "30-35", "35+")))) -> 30-35 | L4: =D4*Q4 -> 0 | M4: =IF(I4="southeast", 1, 0) -> 1 | N4: =IF(I4="southwest", 1, 0) -> 0 | O4: =IF(I4="northwest", 1, 0) -> 0 | P4: 0.52184097 | Q4: =IF(H4="Yes", 1, 0) -> 0 | R4: =IF(F4="yes", 1, 0) -> 1 | S4: =IF(C4="female", 1, 0) -> 0 | T4: =-7277.71 + (-1.28*B4) + (85.5*D4) + (738.24*G4) + (159.59*E4) + (1259.19*L4) + (-3644.73*M4) + (-2956.11*N4) + (-2948.04*O4) + (-17828.85*Q4) + (-69.06*R4) + (444.95*S4) -> 4893.39 | U4: =J4-T4 -> -3757.45
A5: 4 | B5: 38 | C5: male | D5: 33.7 | E5: 80 | F5: No | G5: 0 | H5: No | I5: northwest | J5: 1136.4 | K5: =IF(D5<20, "<20", IF(D5<25, "20-25", IF(D5<30, "25-30", IF(D5<35, "30-35", "35+")))) -> 30-35 | L5: =D5*Q5 -> 0 | M5: =IF(I5="southeast", 1, 0) -> 0 | N5: =IF(I5="southwest", 1, 0) -> 0 | O5: =IF(I5="northwest", 1, 0) -> 1 | P5: 0.67465477 | Q5: =IF(H5="Yes", 1, 0) -> 0 | R5: =IF(F5="yes", 1, 0) -> 0 | S5: =IF(C5="female", 1, 0) -> 0 | T5: =-7277.71 + (-1.28*B5) + (85.5*D5) + (738.24*G5) + (159.59*E5) + (1259.19*L5) + (-3644.73*M5) + (-2956.11*N5) + (-2948.04*O5) + (-17828.85*Q5) + (-69.06*R5) + (444.95*S5) -> 5374.16 | U5: =J5-T5 -> -4237.76
A6: 5 | B6: 38 | C6: male | D6: 34.1 | E6: 100 | F6: No | G6: 0 | H6: No | I6: northwest | J6: 1137.01 | K6: =IF(D6<20, "<20", IF(D6<25, "20-25", IF(D6<30, "25-30", IF(D6<35, "30-35", "35+")))) -> 30-35 | L6: =D6*Q6 -> 0 | M6: =IF(I6="southeast", 1, 0) -> 0 | N6: =IF(I6="southwest", 1, 0) -> 0 | O6: =IF(I6="northwest", 1, 0) -> 1 | P6: 0.84569392 | Q6: =IF(H6="Yes", 1, 0) -> 0 | R6: =IF(F6="yes", 1, 0) -> 0 | S6: =IF(C6="female", 1, 0) -> 0 | T6: =-7277.71 + (-1.28*B6) + (85.5*D6) + (738.24*G6) + (159.59*E6) + (1259.19*L6) + (-3644.73*M6) + (-2956.11*N6) + (-2948.04*O6) + (-17828.85*Q6) + (-69.06*R6) + (444.95*S6) -> 8600.16 | U6: =J6-T6 -> -7463.15
A7: 6 | B7: 38 | C7: male | D7: 34.4 | E7: 96 | F7: Yes | G7: 0 | H7: No | I7: northwest | J7: 1137.47 | K7: =IF(D7<20, "<20", IF(D7<25, "20-25", IF(D7<30, "25-30", IF(D7<35, "30-35", "35+")))) -> 30-35 | L7: =D7*Q7 -> 0 | M7: =IF(I7="southeast", 1, 0) -> 0 | N7: =IF(I7="southwest", 1, 0) -> 0 | O7: =IF(I7="northwest", 1, 0) -> 1 | P7: 0.68910949 | Q7: =IF(H7="Yes", 1, 0) -> 0 | R7: =IF(F7="yes", 1, 0) -> 1 | S7: =IF(C7="female", 1, 0) -> 0 | T7: =-7277.71 + (-1.28*B7) + (85.5*D7) + (738.24*G7) + (159.59*E7) + (1259.19*L7) + (-3644.73*M7) + (-2956.11*N7) + (-2948.04*O7) + (-17828.85*Q7) + (-69.06*R7) + (444.95*S7) -> 7918.39 | U7: =J7-T7 -> -6780.92
A8: 7 | B8: 38 | C8: male | D8: 37.3 | E8: 86 | F8: Yes | G8: 0 | H8: No | I8: northwest | J8: 1141.45 | K8: =IF(D8<20, "<20", IF(D8<25, "20-25", IF(D8<30, "25-30", IF(D8<35, "30-35", "35+")))) -> 35+ | L8: =D8*Q8 -> 0 | M8: =IF(I8="southeast", 1, 0) -> 0 | N8: =IF(I8="southwest", 1, 0) -> 0 | O8: =IF(I8="northwest", 1, 0) -> 1 | P8: 0.16280539 | Q8: =IF(H8="Yes", 1, 0) -> 0 | R8: =IF(F8="yes", 1, 0) -> 1 | S8: =IF(C8="female", 1, 0) -> 0 | T8: =-7277.71 + (-1.28*B8) + (85.5*D8) + (738.24*G8) + (159.59*E8) + (1259.19*L8) + (-3644.73*M8) + (-2956.11*N8) + (-2948.04*O8) + (-17828.85*Q8) + (-69.06*R8) + (444.95*S8) -> 6570.44 | U8: =J8-T8 -> -5428.99
A9: 8 | B9: 19 | C9: male | D9: 41.1 | E9: 100 | F9: No | G9: 0 | H9: No | I9: northwest | J9: 1146.8 | K9: =IF(D9<20, "<20", IF(D9<25, "20-25", IF(D9<30, "25-30", IF(D9<35, "30-35", "35+")))) -> 35+ | L9: =D9*Q9 -> 0 | M9: =IF(I9="southeast", 1, 0) -> 0 | N9: =IF(I9="southwest", 1, 0) -> 0 | O9: =IF(I9="northwest", 1, 0) -> 1 | P9: 0.68992858 | Q9: =IF(H9="Yes", 1, 0) -> 0 | R9: =IF(F9="yes", 1, 0) -> 0 | S9: =IF(C9="female", 1, 0) -> 0 | T9: =-7277.71 + (-1.28*B9) + (85.5*D9) + (738.24*G9) + (159.59*E9) + (1259.19*L9) + (-3644.73*M9) + (-2956.11*N9) + (-2948.04*O9) + (-17828.85*Q9) + (-69.06*R9) + (444.95*S9) -> 9222.98 | U9: =J9-T9 -> -8076.18
A10: 9 | B10: 20 | C10: male | D10: 43 | E10: 86 | F10: No | G10: 0 | H10: No | I10: northwest | J10: 1149.4 | K10: =IF(D10<20, "<20", IF(D10<25, "20-25", IF(D10<30, "25-30", IF(D10<35, "30-35", "35+")))) -> 35+ | L10: =D10*Q10 -> 0 | M10: =IF(I10="southeast", 1, 0) -> 0 | N10: =IF(I10="southwest", 1, 0) -> 0 | O10: =IF(I10="northwest", 1, 0) -> 1 | P10: 0.70153267 | Q10: =IF(H10="Yes", 1, 0) -> 0 | R10: =IF(F10="yes", 1, 0) -> 0 | S10: =IF(C10="female", 1, 0) -> 0 | T10: =-7277.71 + (-1.28*B10) + (85.5*D10) + (738.24*G10) + (159.59*E10) + (1259.19*L10) + (-3644.73*M10) + (-2956.11*N10) + (-2948.04*O10) + (-17828.85*Q10) + (-69.06*R10) + (444.95*S10) -> 7149.89 | U10: =J10-T10 -> -6000.49
A11: 10 | B11: 30 | C11: male | D11: 53.1 | E11: 97 | F11: No | G11: 0 | H11: No | I11: northwest | J11: 1163.46 | K11: =IF(D11<20, "<20", IF(D11<25, "20-25", IF(D11<30, "25-30", IF(D11<35, "30-35", "35+")))) -> 35+ | L11: =D11*Q11 -> 0 | M11: =IF(I11="southeast", 1, 0) -> 0 | N11: =IF(I11="southwest", 1, 0) -> 0 | O11: =IF(I11="northwest", 1, 0) -> 1 | P11: 0.26113331 | Q11: =IF(H11="Yes", 1, 0) -> 0 | R11: =IF(F11="yes", 1, 0) -> 0 | S11: =IF(C11="female", 1, 0) -> 0 | T11: =-7277.71 + (-1.28*B11) + (85.5*D11) + (738.24*G11) + (159.59*E11) + (1259.19*L11) + (-3644.73*M11) + (-2956.11*N11) + (-2948.04*O11) + (-17828.85*Q11) + (-69.06*R11) + (444.95*S11) -> 9756.13 | U11: =J11-T11 -> -8592.67
A12: 11 | B12: 36 | C12: male | D12: 19.8 | E12: 88 | F12: Yes | G12: 0 | H12: No | I12: northwest | J12: 1241.57 | K12: =IF(D12<20, "<20", IF(D12<25, "20-25", IF(D12<30, "25-30", IF(D12<35, "30-35", "35+")))) -> <20 | L12: =D12*Q12 -> 0 | M12: =IF(I12="southeast", 1, 0) -> 0 | N12: =IF(I12="southwest", 1, 0) -> 0 | O12: =IF(I12="northwest", 1, 0) -> 1 | P12: 0.74024268 | Q12: =IF(H12="Yes", 1, 0) -> 0 | R12: =IF(F12="yes", 1, 0) -> 1 | S12: =IF(C12="female", 1, 0) -> 0 | T12: =-7277.71 + (-1.28*B12) + (85.5*D12) + (738.24*G12) + (159.59*E12) + (1259.19*L12) + (-3644.73*M12) + (-2956.11*N12) + (-2948.04*O12) + (-17828.85*Q12) + (-69.06*R12) + (444.95*S12) -> 5395.93 | U12: =J12-T12 -> -4154.36
A13: 12 | B13: 37 | C13: male | D13: 20.3 | E13: 90 | F13: Yes | G13: 0 | H13: No | I13: northwest | J13: 1242.26 | K13: =IF(D13<20, "<20", IF(D13<25, "20-25", IF(D13<30, "25-30", IF(D13<35, "30-35", "35+")))) -> 20-25 | L13: =D13*Q13 -> 0 | M13: =IF(I13="southeast", 1, 0) -> 0 | N13: =IF(I13="southwest", 1, 0) -> 0 | O13: =IF(I13="northwest", 1, 0) -> 1 | P13: 0.83110142 | Q13: =IF(H13="Yes", 1, 0) -> 0 | R13: =IF(F13="yes", 1, 0) -> 1 | S13: =IF(C13="female", 1, 0) -> 0 | T13: =-7277.71 + (-1.28*B13) + (85.5*D13) + (738.24*G13) + (159.59*E13) + (1259.19*L13) + (-3644.73*M13) + (-2956.11*N13) + (-2948.04*O13) + (-17828.85*Q13) + (-69.06*R13) + (444.95*S13) -> 5756.58 | U13: =J13-T13 -> -4514.32
... A1341: 1340 | B1341: 30 | C1341: female | D1341: 47.4 | E1341: 101 | F1341: No | G1341: 0 | H1341: Yes | I1341: southeast | J1341: 63770.43 | K1341: =IF(D1341<20, "<20", IF(D1341<25, "20-25", IF(D1341<30, "25-30", IF(D1341<35, "30-35", "35+")))) -> 35+ | L1341: =D1341*Q1341 -> 47.4 | M1341: =IF(I1341="southeast", 1, 0) -> 1 | N1341: =IF(I1341="southwest", 1, 0) -> 0 | O1341: =IF(I1341="northwest", 1, 0) -> 0 | P1341: 0.44307134 | Q1341: =IF(H1341="Yes", 1, 0) -> 1 | R1341: =IF(F1341="yes", 1, 0) -> 0 | S1341: =IF(C1341="female", 1, 0) -> 1 | T1341: =-7277.71 + (-1.28*B1341) + (85.5*D1341) + (738.24*G1341) + (159.59*E1341) + (1259.19*L1341) + (-3644.73*M1341) + (-2956.11*N1341) + (-2948.04*O1341) + (-17828.85*Q1341) + (-69.06*R1341) + (444.95*S1341) -> 51512.156 | U1341: =J1341-T1341 -> 12258.274
Q1342: =SUM(Q2:Q1341) -> 274 | R1342: =SUM(R2:R1341) -> 642 | S1342: =SUM(S2:S1341) -> 662

Sheet Dashboard
A1: Actuarial Premium Drivers & Model Diagnostic
A3: Smoker vs Non-Smoker Column Chart | O3: BMI Group Column Chart
A20: Children Column Chart | J20: BMI vs Smoking Status | S20: BMI vs Actual Claim
A39: Actual vs Predicted | Q39: Residual Plot
A58: Variable
A59: Variable | B59: Absolute Coefficient
A60: Smoker Penalty | B60: 17828
A61: Region (Southeast) | B61: 3644
A62: BMI × Smoker | B62: 1259
A63: Dependents | B63: 738
A64: Blood Pressure | B64: 159
A65: BMI | B65: 85

Sheet Sheet3
A3: Smokers | B3: Average of claim
A4: Yes | B4: 32050.232
A5: No | B5: 8421.1216
A6: Grand Total | B6: 13252.746
A11: BMI Groups | B11: Average of claim
A12: <20 | B12: 8802.4537
A13: 20-25 | B13: 10456.306
A14: 25-30 | B14: 11000.079
A15: 30-35 | B15: 14298.843
A16: 35+ | B16: 17027.187
A17: Grand Total | B17: 13252.746
A20: Children | B20: Average of claim
A21: 0 | B21: 12327.993
A22: 1 | B22: 12731.172
A23: 2 | B23: 15073.564
A24: 3 | B24: 15355.319
A25: 4 | B25: 13850.657
A26: 5 | B26: 8786.0356
A27: Grand Total | B27: 13252.746

Sheet Regression Summary
A1: SUMMARY OUTPUT
A3: Regression Statistics
A4: Multiple R | B4: 0.88372259
A5: R Square | B5: 0.78096562
A6: Adjusted R Square | B6: 0.7784813
A7: Standard Error | B7: 5560.3393
A8: Observations | B8: 1071
A10: ANOVA
B11: df | C11: SS | D11: MS | E11: F | F11: Significance F
A12: Regression | B12: 12 | C12: 1.1662936e+11 | D12: 9.7191133e+09 | E12: 314.35766 | F12: 0
A13: Residual | B13: 1058 | C13: 3.2710581e+10 | D13: 30917374
A14: Total | B14: 1070 | C14: 1.4933994e+11
B16: Coefficients | C16: Standard Error | D16: t Stat | E16: P-value | F16: Lower 95% | G16: Upper 95% | H16: Lower 95.0% | I16: Upper 95.0%
A17: Intercept | B17: -7277.715 | C17: 2047.1546 | D17: -3.5550393 | E17: 0.00039462245 | F17: -11294.66 | G17: -3260.7704 | H17: -11294.66 | I17: -3260.7704
A18: age | B18: -1.2799913 | C18: 16.821795 | D18: -0.076091248 | E18: 0.93936089 | F18: -34.287864 | G18: 31.727881 | H18: -34.287864 | I18: 31.727881
A19: bmi | B19: 85.500061 | C19: 32.048086 | D19: 2.6678679 | E19: 0.0077500741 | F19: 22.615027 | G19: 148.38509 | H19: 22.615027 | I19: 148.38509
A20: children | B20: 738.2365 | C20: 143.18671 | D20: 5.1557612 | E20: 3.0134736e-07 | F20: 457.27428 | G20: 1019.1987 | H20: 457.27428 | I20: 1019.1987
A21: bloodpressure | B21: 159.58823 | C21: 17.182504 | D21: 9.2878331 | E21: 8.6821502e-20 | F21: 125.87257 | G21: 193.30389 | H21: 125.87257 | I21: 193.30389
A22: BMI_Smoker | B22: 1259.1881 | C22: 68.937947 | D22: 18.26553 | E22: 5.3375416e-65 | F22: 1123.9175 | G22: 1394.4588 | H22: 1123.9175 | I22: 1394.4588
A23: Is Southeast | B23: -3644.731 | C23: 512.57005 | D23: -7.1106983 | E23: 2.122041e-12 | F23: -4650.5004 | G23: -2638.9616 | H23: -4650.5004 | I23: -2638.9616
A24: Is Southwest | B24: -2956.1142 | C24: 549.95704 | D24: -5.3751729 | E24: 9.4106945e-08 | F24: -4035.2447 | G24: -1876.9837 | H24: -4035.2447 | I24: -1876.9837
A25: Is Northwest | B25: -2948.0359 | C25: 526.15022 | D25: -5.6030309 | E25: 2.6852486e-08 | F25: -3980.4525 | G25: -1915.6194 | H25: -3980.4525 | I25: -1915.6194
A26: Randomizer | B26: 601.56146 | C26: 746.94986 | D26: 0.80535722 | E26: 0.42079453 | F26: -864.11008 | G26: 2067.233 | H26: -864.11008 | I26: 2067.233
A27: Is Smoker | B27: -17828.853 | C27: 2120.7781 | D27: -8.4067505 | E27: 1.3477254e-16 | F27: -21990.262 | G27: -13667.443 | H27: -21990.262 | I27: -13667.443
A28: Is Diabetic | B28: -69.062501 | C28: 341.97007 | D28: -0.20195481 | E28: 0.83999088 | F28: -740.07916 | G28: 601.95416 | H28: -740.07916 | I28: 601.95416
A29: Is Female | B29: 444.95201 | C29: 372.24259 | D29: 1.195328 | E29: 0.23222674 | F29: -285.46565 | G29: 1175.3697 | H29: -285.46565 | I29: 1175.3697

Sheet Math Zone
A1: ='insurance final cleaned'!J1 -> claim | B1: ='insurance final cleaned'!B1 -> age | C1: ='insurance final cleaned'!D1 -> bmi | D1: ='insurance final cleaned'!G1 -> children | E1: ='insurance final cleaned'!E1 -> bloodpressure | F1: ='insurance final cleaned'!L1 -> BMI_Smoker | G1: ='insurance final cleaned'!M1 -> Is Southeast | H1: ='insurance final cleaned'!N1 -> Is Southwest | I1: ='insurance final cleaned'!O1 -> Is Northwest | J1: ='insurance final cleaned'!P1 -> Randomizer | K1: ='insurance final cleaned'!Q1 -> Is Smoker | L1: ='insurance final cleaned'!R1 -> Is Diabetic | M1: ='insurance final cleaned'!S1 -> Is Female
A2: ='insurance final cleaned'!J185 -> 2866.09 | B2: ='insurance final cleaned'!B185 -> 37 | C2: ='insurance final cleaned'!D185 -> 27.2 | D2: ='insurance final cleaned'!G185 -> 0 | E2: ='insurance final cleaned'!E185 -> 87 | F2: ='insurance final cleaned'!L185 -> 0 | G2: ='insurance final cleaned'!M185 -> 0 | H2: ='insurance final cleaned'!N185 -> 1 | I2: ='insurance final cleaned'!O185 -> 0 | J2: ='insurance final cleaned'!P185 -> 0.0021653967 | K2: ='insurance final cleaned'!Q185 -> 0 | L2: ='insurance final cleaned'!R185 -> 1 | M2: ='insurance final cleaned'!S185 -> 0
A3: ='insurance final cleaned'!J621 -> 8582.3 | B3: ='insurance final cleaned'!B621 -> 46 | C3: ='insurance final cleaned'!D621 -> 23.9 | D3: ='insurance final cleaned'!G621 -> 5 | E3: ='insurance final cleaned'!E621 -> 96 | F3: ='insurance final cleaned'!L621 -> 0 | G3: ='insurance final cleaned'!M621 -> 1 | H3: ='insurance final cleaned'!N621 -> 0 | I3: ='insurance final cleaned'!O621 -> 0 | J3: ='insurance final cleaned'!P621 -> 0.0032663433 | K3: ='insurance final cleaned'!Q621 -> 0 | L3: ='insurance final cleaned'!R621 -> 0 | M3: ='insurance final cleaned'!S621 -> 1
A4: ='insurance final cleaned'!J217 -> 3277.16 | B4: ='insurance final cleaned'!B217 -> 28 | C4: ='insurance final cleaned'!D217 -> 37.1 | D4: ='insurance final cleaned'!G217 -> 1 | E4: ='insurance final cleaned'!E217 -> 90 | F4: ='insurance final cleaned'!L217 -> 0 | G4: ='insurance final cleaned'!M217 -> 0 | H4: ='insurance final cleaned'!N217 -> 1 | I4: ='insurance final cleaned'!O217 -> 0 | J4: ='insurance final cleaned'!P217 -> 0.0042425221 | K4: ='insurance final cleaned'!Q217 -> 0 | L4: ='insurance final cleaned'!R217 -> 1 | M4: ='insurance final cleaned'!S217 -> 0
A5: ='insurance final cleaned'!J958 -> 14210.54 | B5: ='insurance final cleaned'!B958 -> 47 | C5: ='insurance final cleaned'!D958 -> 37.9 | D5: ='insurance final cleaned'!G958 -> 0 | E5: ='insurance final cleaned'!E958 -> 103 | F5: ='insurance final cleaned'!L958 -> 0 | G5: ='insurance final cleaned'!M958 -> 0 | H5: ='insurance final cleaned'!N958 -> 0 | I5: ='insurance final cleaned'!O958 -> 1 | J5: ='insurance final cleaned'!P958 -> 0.0058230131 | K5: ='insurance final cleaned'!Q958 -> 0 | L5: ='insurance final cleaned'!R958 -> 0 | M5: ='insurance final cleaned'!S958 -> 0
A6: ='insurance final cleaned'!J298 -> 4349.46 | B6: ='insurance final cleaned'!B298 -> 25 | C6: ='insurance final cleaned'!D298 -> 33 | D6: ='insurance final cleaned'!G298 -> 2 | E6: ='insurance final cleaned'!E298 -> 89 | F6: ='insurance final cleaned'!L298 -> 0 | G6: ='insurance final cleaned'!M298 -> 1 | H6: ='insurance final cleaned'!N298 -> 0 | I6: ='insurance final cleaned'!O298 -> 0 | J6: ='insurance final cleaned'!P298 -> 0.006167094 | K6: ='insurance final cleaned'!Q298 -> 0 | L6: ='insurance final cleaned'!R298 -> 1 | M6: ='insurance final cleaned'!S298 -> 1
A7: ='insurance final cleaned'!J252 -> 3756.62 | B7: ='insurance final cleaned'!B252 -> 45 | C7: ='insurance final cleaned'!D252 -> 25.7 | D7: ='insurance final cleaned'!G252 -> 0 | E7: ='insurance final cleaned'!E252 -> 80 | F7: ='insurance final cleaned'!L252 -> 0 | G7: ='insurance final cleaned'!M252 -> 1 | H7: ='insurance final cleaned'!N252 -> 0 | I7: ='insurance final cleaned'!O252 -> 0 | J7: ='insurance final cleaned'!P252 -> 0.0072101472 | K7: ='insurance final cleaned'!Q252 -> 0 | L7: ='insurance final cleaned'!R252 -> 0 | M7: ='insurance final cleaned'!S252 -> 1
A8: ='insurance final cleaned'!J1206 -> 34806.47 | B8: ='insurance final cleaned'!B1206 -> 32 | C8: ='insurance final cleaned'!D1206 -> 31.1 | D8: ='insurance final cleaned'!G1206 -> 1 | E8: ='insurance final cleaned'!E1206 -> 114 | F8: ='insurance final cleaned'!L1206 -> 31.1 | G8: ='insurance final cleaned'!M1206 -> 1 | H8: ='insurance final cleaned'!N1206 -> 0 | I8: ='insurance final cleaned'!O1206 -> 0 | J8: ='insurance final cleaned'!P1206 -> 0.0072673761 | K8: ='insurance final cleaned'!Q1206 -> 1 | L8: ='insurance final cleaned'!R1206 -> 1 | M8: ='insurance final cleaned'!S1206 -> 0
A9: ='insurance final cleaned'!J1214 -> 35595.59 | B9: ='insurance final cleaned'!B1214 -> 56 | C9: ='insurance final cleaned'!D1214 -> 31 | D9: ='insurance final cleaned'!G1214 -> 3 | E9: ='insurance final cleaned'!E1214 -> 129 | F9: ='insurance final cleaned'!L1214 -> 31 | G9: ='insurance final cleaned'!M1214 -> 1 | H9: ='insurance final cleaned'!N1214 -> 0 | I9: ='insurance final cleaned'!O1214 -> 0 | J9: ='insurance final cleaned'!P1214 -> 0.0073824174 | K9: ='insurance final cleaned'!Q1214 -> 1 | L9: ='insurance final cleaned'!R1214 -> 1 | M9: ='insurance final cleaned'!S1214 -> 1
A10: ='insurance final cleaned'!J629 -> 8627.54 | B10: ='insurance final cleaned'!B629 -> 43 | C10: ='insurance final cleaned'!D629 -> 19.2 | D10: ='insurance final cleaned'!G629 -> 1 | E10: ='insurance final cleaned'!E629 -> 99 | F10: ='insurance final cleaned'!L629 -> 0 | G10: ='insurance final cleaned'!M629 -> 0 | H10: ='insurance final cleaned'!N629 -> 0 | I10: ='insurance final cleaned'!O629 -> 0 | J10: ='insurance final cleaned'!P629 -> 0.0082772036 | K10: ='insurance final cleaned'!Q629 -> 0 | L10: ='insurance final cleaned'!R629 -> 1 | M10: ='insurance final cleaned'!S629 -> 0
A11: ='insurance final cleaned'!J616 -> 8539.67 | B11: ='insurance final cleaned'!B616 -> 26 | C11: ='insurance final cleaned'!D616 -> 23.6 | D11: ='insurance final cleaned'!G616 -> 1 | E11: ='insurance final cleaned'!E616 -> 92 | F11: ='insurance final cleaned'!L616 -> 0 | G11: ='insurance final cleaned'!M616 -> 0 | H11: ='insurance final cleaned'!N616 -> 1 | I11: ='insurance final cleaned'!O616 -> 0 | J11: ='insurance final cleaned'!P616 -> 0.0097481891 | K11: ='insurance final cleaned'!Q616 -> 0 | L11: ='insurance final cleaned'!R616 -> 1 | M11: ='insurance final cleaned'!S616 -> 1
A12: ='insurance final cleaned'!J873 -> 12404.88 | B12: ='insurance final cleaned'!B873 -> 43 | C12: ='insurance final cleaned'!D873 -> 35.2 | D12: ='insurance final cleaned'!G873 -> 0 | E12: ='insurance final cleaned'!E873 -> 107 | F12: ='insurance final cleaned'!L873 -> 0 | G12: ='insurance final cleaned'!M873 -> 0 | H12: ='insurance final cleaned'!N873 -> 0 | I12: ='insurance final cleaned'!O873 -> 0 | J12: ='insurance final cleaned'!P873 -> 0.01023297 | K12: ='insurance final cleaned'!Q873 -> 0 | L12: ='insurance final cleaned'!R873 -> 1 | M12: ='insurance final cleaned'!S873 -> 0
A13: ='insurance final cleaned'!J600 -> 8334.59 | B13: ='insurance final cleaned'!B600 -> 40 | C13: ='insurance final cleaned'!D600 -> 33.4 | D13: ='insurance final cleaned'!G600 -> 1 | E13: ='insurance final cleaned'!E600 -> 94 | F13: ='insurance final cleaned'!L600 -> 0 | G13: ='insurance final cleaned'!M600 -> 0 | H13: ='insurance final cleaned'!N600 -> 0 | I13: ='insurance final cleaned'!O600 -> 0 | J13: ='insurance final cleaned'!P600 -> 0.010911074 | K13: ='insurance final cleaned'!Q600 -> 0 | L13: ='insurance final cleaned'!R600 -> 0 | M13: ='insurance final cleaned'!S600 -> 0
A14: ='insurance final cleaned'!J1195 -> 33750.29 | B14: ='insurance final cleaned'!B1195 -> 46 | C14: ='insurance final cleaned'!D1195 -> 31.9 | D14: ='insurance final cleaned'!G1195 -> 0 | E14: ='insurance final cleaned'!E1195 -> 82 | F14: ='insurance final cleaned'!L1195 -> 31.9 | G14: ='insurance final cleaned'!M1195 -> 0 | H14: ='insurance final cleaned'!N1195 -> 0 | I14: ='insurance final cleaned'!O1195 -> 1 | J14: ='insurance final cleaned'!P1195 -> 0.011240829 | K14: ='insurance final cleaned'!Q1195 -> 1 | L14: ='insurance final cleaned'!R1195 -> 1 | M14: ='insurance final cleaned'!S1195 -> 0
A15: ='insurance final cleaned'!J1157 -> 27000.98 | B15: ='insurance final cleaned'!B1157 -> 28 | C15: ='insurance final cleaned'!D1157 -> 31.5 | D15: ='insurance final cleaned'!G1157 -> 1 | E15: ='insurance final cleaned'!E1157 -> 94 | F15: ='insurance final cleaned'!L1157 -> 0 | G15: ='insurance final cleaned'!M1157 -> 1 | H15: ='insurance final cleaned'!N1157 -> 0 | I15: ='insurance final cleaned'!O1157 -> 0 | J15: ='insurance final cleaned'!P1157 -> 0.011857175 | K15: ='insurance final cleaned'!Q1157 -> 0 | L15: ='insurance final cleaned'!R1157 -> 1 | M15: ='insurance final cleaned'!S1157 -> 0
A16: ='insurance final cleaned'!J92 -> 1981.58 | B16: ='insurance final cleaned'!B92 -> 19 | C16: ='insurance final cleaned'!D92 -> 32 | D16: ='insurance final cleaned'!G92 -> 0 | E16: ='insurance final cleaned'!E92 -> 100 | F16: ='insurance final cleaned'!L92 -> 0 | G16: ='insurance final cleaned'!M92 -> 1 | H16: ='insurance final cleaned'!N92 -> 0 | I16: ='insurance final cleaned'!O92 -> 0 | J16: ='insurance final cleaned'!P92 -> 0.012203717 | K16: ='insurance final cleaned'!Q92 -> 0 | L16: ='insurance final cleaned'!R92 -> 1 | M16: ='insurance final cleaned'!S92 -> 0
A17: ='insurance final cleaned'!J721 -> 10106.13 | B17: ='insurance final cleaned'!B721 -> 27 | C17: ='insurance final cleaned'!D721 -> 27.1 | D17: ='insurance final cleaned'!G721 -> 1 | E17: ='insurance final cleaned'!E721 -> 103 | F17: ='insurance final cleaned'!L721 -> 0 | G17: ='insurance final cleaned'!M721 -> 0 | H17: ='insurance final cleaned'!N721 -> 0 | I17: ='insurance final cleaned'!O721 -> 0 | J17: ='insurance final cleaned'!P721 -> 0.012306171 | K17: ='insurance final cleaned'!Q721 -> 0 | L17: ='insurance final cleaned'!R721 -> 0 | M17: ='insurance final cleaned'!S721 -> 1
A18: ='insurance final cleaned'!J317 -> 4504.66 | B18: ='insurance final cleaned'!B317 -> 44 | C18: ='insurance final cleaned'!D317 -> 33.7 | D18: ='insurance final cleaned'!G317 -> 4 | E18: ='insurance final cleaned'!E317 -> 96 | F18: ='insurance final cleaned'!L317 -> 0 | G18: ='insurance final cleaned'!M317 -> 1 | H18: ='insurance final cleaned'!N317 -> 0 | I18: ='insurance final cleaned'!O317 -> 0 | J18: ='insurance final cleaned'!P317 -> 0.012629175 | K18: ='insurance final cleaned'!Q317 -> 0 | L18: ='insurance final cleaned'!R317 -> 0 | M18: ='insurance final cleaned'!S317 -> 0
A19: ='insurance final cleaned'!J700 -> 9788.87 | B19: ='insurance final cleaned'!B700 -> 25 | C19: ='insurance final cleaned'!D700 -> 24.3 | D19: ='insurance final cleaned'!G700 -> 5 | E19: ='insurance final cleaned'!E700 -> 89 | F19: ='insurance final cleaned'!L700 -> 0 | G19: ='insurance final cleaned'!M700 -> 1 | H19: ='insurance final cleaned'!N700 -> 0 | I19: ='insurance final cleaned'!O700 -> 0 | J19: ='insurance final cleaned'!P700 -> 0.01369681 | K19: ='insurance final cleaned'!Q700 -> 0 | L19: ='insurance final cleaned'!R700 -> 0 | M19: ='insurance final cleaned'!S700 -> 0
A20: ='insurance final cleaned'!J1263 -> 40003.33 | B20: ='insurance final cleaned'!B1263 -> 40 | C20: ='insurance final cleaned'!D1263 -> 32.8 | D20: ='insurance final cleaned'!G1263 -> 2 | E20: ='insurance final cleaned'!E1263 -> 107 | F20: ='insurance final cleaned'!L1263 -> 32.8 | G20: ='insurance final cleaned'!M1263 -> 0 | H20: ='insurance final cleaned'!N1263 -> 0 | I20: ='insurance final cleaned'!O1263 -> 1 | J20: ='insurance final cleaned'!P1263 -> 0.014187797 | K20: ='insurance final cleaned'!Q1263 -> 1 | L20: ='insurance final cleaned'!R1263 -> 1 | M20: ='insurance final cleaned'!S1263 -> 1
A21: ='insurance final cleaned'!J195 -> 3044.21 | B21: ='insurance final cleaned'!B195 -> 54 | C21: ='insurance final cleaned'!D195 -> 25.3 | D21: ='insurance final cleaned'!G195 -> 0 | E21: ='insurance final cleaned'!E195 -> 100 | F21: ='insurance final cleaned'!L195 -> 0 | G21: ='insurance final cleaned'!M195 -> 0 | H21: ='insurance final cleaned'!N195 -> 0 | I21: ='insurance final cleaned'!O195 -> 0 | J21: ='insurance final cleaned'!P195 -> 0.014418806 | K21: ='insurance final cleaned'!Q195 -> 0 | L21: ='insurance final cleaned'!R195 -> 0 | M21: ='insurance final cleaned'!S195 -> 1
A22: ='insurance final cleaned'!J424 -> 5926.85 | B22: ='insurance final cleaned'!B424 -> 27 | C22: ='insurance final cleaned'!D424 -> 28.9 | D22: ='insurance final cleaned'!G424 -> 3 | E22: ='insurance final cleaned'!E424 -> 94 | F22: ='insurance final cleaned'!L424 -> 0 | G22: ='insurance final cleaned'!M424 -> 0 | H22: ='insurance final cleaned'!N424 -> 1 | I22: ='insurance final cleaned'!O424 -> 0 | J22: ='insurance final cleaned'!P424 -> 0.01517424 | K22: ='insurance final cleaned'!Q424 -> 0 | L22: ='insurance final cleaned'!R424 -> 1 | M22: ='insurance final cleaned'!S424 -> 0
A23: ='insurance final cleaned'!J63 -> 1727.79 | B23: ='insurance final cleaned'!B63 -> 32 | C23: ='insurance final cleaned'!D63 -> 17.8 | D23: ='insurance final cleaned'!G63 -> 0 | E23: ='insurance final cleaned'!E63 -> 90 | F23: ='insurance final cleaned'!L63 -> 0 | G23: ='insurance final cleaned'!M63 -> 0 | H23: ='insurance final cleaned'!N63 -> 1 | I23: ='insurance final cleaned'!O63 -> 0 | J23: ='insurance final cleaned'!P63 -> 0.01654842 | K23: ='insurance final cleaned'!Q63 -> 0 | L23: ='insurance final cleaned'!R63 -> 0 | M23: ='insurance final cleaned'!S63 -> 1
A24: ='insurance final cleaned'!J406 -> 5488.26 | B24: ='insurance final cleaned'!B406 -> 23 | C24: ='insurance final cleaned'!D406 -> 31 | D24: ='insurance final cleaned'!G406 -> 1 | E24: ='insurance final cleaned'!E406 -> 90 | F24: ='insurance final cleaned'!L406 -> 0 | G24: ='insurance final cleaned'!M406 -> 0 | H24: ='insurance final cleaned'!N406 -> 1 | I24: ='insurance final cleaned'!O406 -> 0 | J24: ='insurance final cleaned'!P406 -> 0.016908177 | K24: ='insurance final cleaned'!Q406 -> 0 | L24: ='insurance final cleaned'!R406 -> 0 | M24: ='insurance final cleaned'!S406 -> 0
A25: ='insurance final cleaned'!J1160 -> 27218.44 | B25: ='insurance final cleaned'!B1160 -> 20 | C25: ='insurance final cleaned'!D1160 -> 29 | D25: ='insurance final cleaned'!G1160 -> 0 | E25: ='insurance final cleaned'!E1160 -> 101 | F25: ='insurance final cleaned'!L1160 -> 29 | G25: ='insurance final cleaned'!M1160 -> 0 | H25: ='insurance final cleaned'!N1160 -> 0 | I25: ='insurance final cleaned'!O1160 -> 0 | J25: ='insurance final cleaned'!P1160 -> 0.019518898 | K25: ='insurance final cleaned'!Q1160 -> 1 | L25: ='insurance final cleaned'!R1160 -> 0 | M25: ='insurance final cleaned'!S1160 -> 0
A26: ='insurance final cleaned'!J60 -> 1720.35 | B26: ='insurance final cleaned'!B60 -> 50 | C26: ='insurance final cleaned'!D60 -> 30 | D26: ='insurance final cleaned'!G60 -> 1 | E26: ='insurance final cleaned'!E60 -> 88 | F26: ='insurance final cleaned'!L60 -> 0 | G26: ='insurance final cleaned'!M60 -> 1 | H26: ='insurance final cleaned'!N60 -> 0 | I26: ='insurance final cleaned'!O60 -> 0 | J26: ='insurance final cleaned'!P60 -> 0.020688349 | K26: ='insurance final cleaned'!Q60 -> 0 | L26: ='insurance final cleaned'!R60 -> 0 | M26: ='insurance final cleaned'!S60 -> 0
A27: ='insurance final cleaned'!J1043 -> 18838.7 | B27: ='insurance final cleaned'!B1043 -> 30 | C27: ='insurance final cleaned'!D1043 -> 27.9 | D27: ='insurance final cleaned'!G1043 -> 3 | E27: ='insurance final cleaned'!E1043 -> 84 | F27: ='insurance final cleaned'!L1043 -> 0 | G27: ='insurance final cleaned'!M1043 -> 0 | H27: ='insurance final cleaned'!N1043 -> 0 | I27: ='insurance final cleaned'!O1043 -> 1 | J27: ='insurance final cleaned'!P1043 -> 0.020881426 | K27: ='insurance final cleaned'!Q1043 -> 0 | L27: ='insurance final cleaned'!R1043 -> 0 | M27: ='insurance final cleaned'!S1043 -> 1
A28: ='insurance final cleaned'!J411 -> 5649.72 | B28: ='insurance final cleaned'!B411 -> 54 | C28: ='insurance final cleaned'!D411 -> 32.8 | D28: ='insurance final cleaned'!G411 -> 0 | E28: ='insurance final cleaned'!E411 -> 86 | F28: ='insurance final cleaned'!L411 -> 0 | G28: ='insurance final cleaned'!M411 -> 0 | H28: ='insurance final cleaned'!N411 -> 1 | I28: ='insurance final cleaned'!O411 -> 0 | J28: ='insurance final cleaned'!P411 -> 0.021349953 | K28: ='insurance final cleaned'!Q411 -> 0 | L28: ='insurance final cleaned'!R411 -> 1 | M28: ='insurance final cleaned'!S411 -> 1
A29: ='insurance final cleaned'!J520 -> 7162.01 | B29: ='insurance final cleaned'!B520 -> 19 | C29: ='insurance final cleaned'!D520 -> 37.2 | D29: ='insurance final cleaned'!G520 -> 2 | E29: ='insurance final cleaned'!E520 -> 96 | F29: ='insurance final cleaned'!L520 -> 0 | G29: ='insurance final cleaned'!M520 -> 1 | H29: ='insurance final cleaned'!N520 -> 0 | I29: ='insurance final cleaned'!O520 -> 0 | J29: ='insurance final cleaned'!P520 -> 0.02217935 | K29: ='insurance final cleaned'!Q520 -> 0 | L29: ='insurance final cleaned'!R520 -> 1 | M29: ='insurance final cleaned'!S520 -> 0
A30: ='insurance final cleaned'!J38 -> 1632.04 | B30: ='insurance final cleaned'!B38 -> 48 | C30: ='insurance final cleaned'!D38 -> 25.2 | D30: ='insurance final cleaned'!G38 -> 0 | E30: ='insurance final cleaned'!E38 -> 98 | F30: ='insurance final cleaned'!L38 -> 0 | G30: ='insurance final cleaned'!M38 -> 0 | H30: ='insurance final cleaned'!N38 -> 0 | I30: ='insurance final cleaned'!O38 -> 1 | J30: ='insurance final cleaned'!P38 -> 0.023809641 | K30: ='insurance final cleaned'!Q38 -> 0 | L30: ='insurance final cleaned'!R38 -> 0 | M30: ='insurance final cleaned'!S38 -> 0
A31: ='insurance final cleaned'!J1245 -> 38709.18 | B31: ='insurance final cleaned'!B1245 -> 29 | C31: ='insurance final cleaned'!D1245 -> 35.2 | D31: ='insurance final cleaned'!G1245 -> 1 | E31: ='insurance final cleaned'!E1245 -> 85 | F31: ='insurance final cleaned'!L1245 -> 35.2 | G31: ='insurance final cleaned'!M1245 -> 1 | H31: ='insurance final cleaned'!N1245 -> 0 | I31: ='insurance final cleaned'!O1245 -> 0 | J31: ='insurance final cleaned'!P1245 -> 0.023900099 | K31: ='insurance final cleaned'!Q1245 -> 1 | L31: ='insurance final cleaned'!R1245 -> 0 | M31: ='insurance final cleaned'!S1245 -> 0
A32: ='insurance final cleaned'!J1196 -> 33900.65 | B32: ='insurance final cleaned'!B1196 -> 48 | C32: ='insurance final cleaned'!D1196 -> 30.2 | D32: ='insurance final cleaned'!G1196 -> 0 | E32: ='insurance final cleaned'!E1196 -> 129 | F32: ='insurance final cleaned'!L1196 -> 30.2 | G32: ='insurance final cleaned'!M1196 -> 0 | H32: ='insurance final cleaned'!N1196 -> 1 | I32: ='insurance final cleaned'!O1196 -> 0 | J32: ='insurance final cleaned'!P1196 -> 0.024572739 | K32: ='insurance final cleaned'!Q1196 -> 1 | L32: ='insurance final cleaned'!R1196 -> 1 | M32: ='insurance final cleaned'!S1196 -> 1
A33: ='insurance final cleaned'!J231 -> 3471.41 | B33: ='insurance final cleaned'!B231 -> 42 | C33: ='insurance final cleaned'!D231 -> 38.9 | D33: ='insurance final cleaned'!G231 -> 1 | E33: ='insurance final cleaned'!E231 -> 94 | F33: ='insurance final cleaned'!L231 -> 0 | G33: ='insurance final cleaned'!M231 -> 1 | H33: ='insurance final cleaned'!N231 -> 0 | I33: ='insurance final cleaned'!O231 -> 0 | J33: ='insurance final cleaned'!P231 -> 0.026428223 | K33: ='insurance final cleaned'!Q231 -> 0 | L33: ='insurance final cleaned'!R231 -> 0 | M33: ='insurance final cleaned'!S231 -> 0
A34: ='insurance final cleaned'!J78 -> 1842.52 | B34: ='insurance final cleaned'!B78 -> 38 | C34: ='insurance final cleaned'!D78 -> 28.4 | D34: ='insurance final cleaned'!G78 -> 1 | E34: ='insurance final cleaned'!E78 -> 87 | F34: ='insurance final cleaned'!L78 -> 0 | G34: ='insurance final cleaned'!M78 -> 0 | H34: ='insurance final cleaned'!N78 -> 1 | I34: ='insurance final cleaned'!O78 -> 0 | J34: ='insurance final cleaned'!P78 -> 0.027157038 | K34: ='insurance final cleaned'!Q78 -> 0 | L34: ='insurance final cleaned'!R78 -> 0 | M34: ='insurance final cleaned'!S78 -> 0
A35: ='insurance final cleaned'!J640 -> 8827.21 | B35: ='insurance final cleaned'!B640 -> 31 | C35: ='insurance final cleaned'!D640 -> 26.4 | D35: ='insurance final cleaned'!G640 -> 0 | E35: ='insurance final cleaned'!E640 -> 100 | F35: ='insurance final cleaned'!L640 -> 0 | G35: ='insurance final cleaned'!M640 -> 0 | H35: ='insurance final cleaned'!N640 -> 0 | I35: ='insurance final cleaned'!O640 -> 1 | J35: ='insurance final cleaned'!P640 -> 0.027181772 | K35: ='insurance final cleaned'!Q640 -> 0 | L35: ='insurance final cleaned'!R640 -> 1 | M35: ='insurance final cleaned'!S640 -> 0
A36: ='insurance final cleaned'!J74 -> 1826.84 | B36: ='insurance final cleaned'!B74 -> 22 | C36: ='insurance final cleaned'!D74 -> 34.4 | D36: ='insurance final cleaned'!G74 -> 0 | E36: ='insurance final cleaned'!E74 -> 98 | F36: ='insurance final cleaned'!L74 -> 0 | G36: ='insurance final cleaned'!M74 -> 0 | H36: ='insurance final cleaned'!N74 -> 1 | I36: ='insurance final cleaned'!O74 -> 0 | J36: ='insurance final cleaned'!P74 -> 0.027306245 | K36: ='insurance final cleaned'!Q74 -> 0 | L36: ='insurance final cleaned'!R74 -> 1 | M36: ='insurance final cleaned'!S74 -> 0
A37: ='insurance final cleaned'!J845 -> 11938.26 | B37: ='insurance final cleaned'!B845 -> 44 | C37: ='insurance final cleaned'!D845 -> 30.3 | D37: ='insurance final cleaned'!G845 -> 0 | E37: ='insurance final cleaned'!E845 -> 102 | F37: ='insurance final cleaned'!L845 -> 0 | G37: ='insurance final cleaned'!M845 -> 0 | H37: ='insurance final cleaned'!N845 -> 0 | I37: ='insurance final cleaned'!O845 -> 0 | J37: ='insurance final cleaned'!P845 -> 0.029130317 | K37: ='insurance final cleaned'!Q845 -> 0 | L37: ='insurance final cleaned'!R845 -> 1 | M37: ='insurance final cleaned'!S845 -> 0
A38: ='insurance final cleaned'!J105 -> 2128.43 | B38: ='insurance final cleaned'!B105 -> 42 | C38: ='insurance final cleaned'!D105 -> 30.5 | D38: ='insurance final cleaned'!G105 -> 0 | E38: ='insurance final cleaned'!E105 -> 99 | F38: ='insurance final cleaned'!L105 -> 0 | G38: ='insurance final cleaned'!M105 -> 0 | H38: ='insurance final cleaned'!N105 -> 0 | I38: ='insurance final cleaned'!O105 -> 1 | J38: ='insurance final cleaned'!P105 -> 0.03010446 | K38: ='insurance final cleaned'!Q105 -> 0 | L38: ='insurance final cleaned'!R105 -> 0 | M38: ='insurance final cleaned'!S105 -> 1
A39: ='insurance final cleaned'!J748 -> 10579.71 | B39: ='insurance final cleaned'!B748 -> 55 | C39: ='insurance final cleaned'!D748 -> 39.6 | D39: ='insurance final cleaned'!G748 -> 1 | E39: ='insurance final cleaned'!E748 -> 91 | F39: ='insurance final cleaned'!L748 -> 0 | G39: ='insurance final cleaned'!M748 -> 1 | H39: ='insurance final cleaned'!N748 -> 0 | I39: ='insurance final cleaned'!O748 -> 0 | J39: ='insurance final cleaned'!P748 -> 0.030128125 | K39: ='insurance final cleaned'!Q748 -> 0 | L39: ='insurance final cleaned'!R748 -> 0 | M39: ='insurance final cleaned'!S748 -> 1
A40: ='insurance final cleaned'!J484 -> 6664.69 | B40: ='insurance final cleaned'!B484 -> 29 | C40: ='insurance final cleaned'!D484 -> 28.4 | D40: ='insurance final cleaned'!G484 -> 1 | E40: ='insurance final cleaned'!E484 -> 87 | F40: ='insurance final cleaned'!L484 -> 0 | G40: ='insurance final cleaned'!M484 -> 0 | H40: ='insurance final cleaned'!N484 -> 0 | I40: ='insurance final cleaned'!O484 -> 1 | J40: ='insurance final cleaned'!P484 -> 0.030497679 | K40: ='insurance final cleaned'!Q484 -> 0 | L40: ='insurance final cleaned'!R484 -> 0 | M40: ='insurance final cleaned'!S484 -> 0
...
